File: assets/FLAT_COPT_CO3NM_PARALELO_00001.dat
[Header]
; VSM Data File (default extension .dat)
; Copyright (c) 2003-2008, Quantum Design, Inc. All rights reserved.
TITLE,
FILEOPENTIME,3931695930.39377,08/01/2024,5:45 pm
BYAPP,VSM,2.0,1.0
INFO,VersaLab VSM Option Release 1.4.4 Build 11,APPNAME
INFO,Quantum Design Linear Motor Servo Controller,MOTOR_MODULE_NAME
INFO,3101-100 E4,MOTOR_HW_VERSION
INFO,MMC480,MOTOR_SERIAL_NUMBER
INFO,SRV No X-over 01.03.11,MOTOR_SOFTWARE_VERSION
INFO,Quantum Design VSM Detection Module,VSM_MODULE_NAME
INFO,3101-150 D1,VSM_HW_VERSION
INFO,285,VSM_SERIAL_NUMBER
INFO,VSM No X-over 01.02.05 May 20 2008 13:51:47,VSM_SOFTWARE_VERSION
INFO,279,PREAMP_SERIAL_NUMBER
INFO,835,COIL_SERIAL_NUMBER
INFO,0,MOMENT_UNITS
INFO,,SAMPLE_MATERIAL
INFO,,SAMPLE_COMMENT
INFO,,SAMPLE_MASS
INFO,,SAMPLE_VOLUME
INFO,,SAMPLE_MOLECULAR_WEIGHT
INFO,,SAMPLE_SIZE
INFO,,SAMPLE_SHAPE
DATATYPE,COMMENT,1
DATATYPE,TIME,2
STARTUPAXIS,X,2
STARTUPAXIS,Y1,5
[Data]
Comment,Time Stamp (sec),Temperature (K),Magnetic Field (Oe),Moment (emu),M. Std. Err. (emu),Transport Action,Averaging Time (sec),Frequency (Hz),Peak Amplitude (mm),Center Position (mm),Coil Signal' (mV),Coil Signal" (mV),Range (mV),M. Quad. Signal (emu),M. Raw' (emu),M. Raw" (emu),Min. Temperature (K),Max. Temperature (K),Min. Field (Oe),Max. Field (Oe),Mass (grams),Motor Lag (deg),Pressure (Torr),VSM Status (code),Motor Status (code),Measure Status (code),Measure Count,System Temp. (K),Temp. Status (code),Field Status (code),Chamber Status (code),Motor Current (amps),Motor Heatsink Temp. (C),Map 01,Map 02,Map 03,Map 04,Map 05,Map 06,Map 07,Map 08,Map 09,Map 10,Map 11,Map 12,Map 13,Map 14,Map 15,Map 16
,3931695989.7125,299.909912109375,14917.111328125,0.0010339489931984,5.63932031390343E-6,1,1.99850670813958,40.0298881530762,1.99818389602886,15.1500003412366,0.011924699794261,0.00201066904337608,0.25,-7.81870230316126E-6,0.00103392231916425,-7.14820426298603E-6,299.909759521484,299.909759521484,14834.1875,15000.03515625,46.0418279252933,17.1732910704338,,0,0,0,80,299.912200927734,1,4,4,1.91665649414062,54.2522010803223,,,,,,,,,,,,,,,,
,3931696023.684,299.911270141602,14507.3759765625,0.00104663199616401,6.29981477584812E-6,1,1.99850670813958,40.0298881530762,1.9986281106315,15.1699995622039,0.0120779138817608,0.00201113322625337,0.25,-1.00532132872274E-5,0.00104660634573941,-9.37440336307504E-6,299.91162109375,299.91162109375,14488.28125,14526.470703125,47.648856160832,17.1888539715471,,0,0,0,80,299.912353515625,1,6,4,1.93588256835938,56.6959953308105,,,,,,,,,,,,,,,,
,3931696051.6715,299.9111328125,13949.8715820312,0.00106466541535632,5.09562647140809E-6,1,1.99850670813958,40.0298881530762,1.99875435876821,15.1699995622039,0.0122848210101037,0.00205693450918882,0.25,-9.26954274173056E-6,0.00106463870290491,-8.57903184292977E-6,299.911926269531,299.911926269531,13929.794921875,13969.9482421875,47.757502525005,17.1896141840035,,0,0,0,80,299.911926269531,1,6,4,1.92611694335938,58.1622695922852,,,,,,,,,,,,,,,,
,3931696079.65,299.911346435547,13393.5966796875,0.00107662469551359,5.54501976371979E-6,1,1.99850670813958,40.0298881530762,1.99866039635895,15.1699995622039,0.0124254982715974,0.00206153510137906,0.25,-1.09717481302939E-5,0.00107659871054028,-1.02733979953628E-5,299.91162109375,299.91162109375,13373.4423828125,13413.7509765625,47.7856411516974,17.1912791656338,,0,0,0,80,299.91162109375,1,6,4,1.92520141601562,58.6510276794434,,,,,,,,,,,,,,,,
,3931696107.5985,299.911697387695,12835.447265625,0.00109390390463609,5.60183654561847E-6,1,1.99850670813958,40.0298881530762,1.99866708983324,15.1699995622039,0.0126243722540048,0.00209796651698003,0.25,-1.08581096688867E-5,0.00109387730262726,-1.01485266239268E-5,299.912200927734,299.912200927734,12815.4560546875,12855.4384765625,47.8356653769281,17.1933214100335,,0,0,0,80,299.911193847656,1,6,4,1.9244384765625,59.6285438537598,,,,,,,,,,,,,,,,
,3931696135.587,299.912994384766,12279.4829101562,0.00111110860506044,5.31866756452842E-6,1,1.99850670813958,40.0298881530762,1.99835245766464,15.1699995622039,0.0128234573836652,0.00211656391313838,0.25,-1.22508140534957E-5,0.0011110823400529,-1.15300018795387E-5,299.913787841797,299.913787841797,12259.4228515625,12299.54296875,47.5722565659473,17.2202146751193,,0,0,0,80,299.912200927734,1,6,4,1.9293212890625,60.117301940918,,,,,,,,,,,,,,,,
,3931696163.5595,299.913208007812,11723.1000976563,0.00112672835611246,1.14256808634014E-6,1,1.99850670813958,40.0298881530762,1.99823116480965,15.1699995622039,0.0130054220893103,0.00213225863146878,0.25,-1.36327866655543E-5,0.00112670249751856,-1.2901769847616E-5,299.914215087891,299.914215087891,11702.7783203125,11743.421875,47.9505647692551,17.2373305671481,,0,0,0,80,299.912200927734,1,6,1,1.92794799804687,60.6060638427734,,,,,,,,,,,,,,,,
,3931696191.534,299.912628173828,11165.6396484375,0.00113903304002971,8.69710390876376E-7,1,1.99850670813958,40.0298881530762,1.99785094833022,15.1699995622039,0.0131376911992705,0.00219676828329425,0.25,-1.0167562874613E-5,0.00113900456778328,-9.4286375457512E-6,299.912780761719,299.912780761719,11146.81640625,11184.462890625,47.3072844979281,17.2340164495145,,0,0,0,80,299.912475585937,1,6,1,1.9342041015625,61.5835800170898,,,,,,,,,,,,,,,,
,3931696219.506,299.91242980957,10607.9599609375,0.00115387916173722,9.86507428739765E-7,1,1.99850670813958,40.0298881530762,1.99745398675537,15.1699995622039,0.0133171390659214,0.00216393434996224,0.25,-1.56015490745433E-5,0.00115385375841372,-1.48527937359774E-5,299.911926269531,299.911926269531,10587.720703125,10628.19921875,47.6926273579089,17.2420884579965,,0,0,0,80,299.912933349609,1,6,1,1.93893432617187,61.5835800170898,,,,,,,,,,,,,,,,
,3931696247.525,299.913208007812,10052.048828125,0.00116560879552837,1.04875762514174E-6,1,1.99850670813958,40.0298881530762,1.99731910590332,15.1699995622039,0.0134466151981603,0.00221424421582104,0.25,-1.32885896896379E-5,0.00116558150681604,-1.25322661106512E-5,299.912933349609,299.912933349609,10032.005859375,10072.091796875,47.5597505096396,17.2395314944158,,0,0,0,80,299.913482666016,1,6,1,1.9073486328125,62.0723381042481,,,,,,,,,,,,,,,,
,3931696275.481,299.913619995117,9495.23095703125,0.00117663499565808,8.48591432904234E-7,1,1.99850670813958,40.0298881530762,1.99711085990626,15.1699995622039,0.0135640831532167,0.00228237781505265,0.25,-9.29569135585036E-6,0.00117660476321269,-8.53230626995829E-6,299.914764404297,299.914764404297,9475.0810546875,9515.380859375,47.689500843832,17.246287800553,,0,0,0,80,299.912475585937,1,6,1,1.92108154296875,62.0723381042481,,,,,,,,,,,,,,,,
,3931696303.48,299.913635253906,8941.85107421875,0.0011917008016902,1.04441115092832E-6,1,1.99850670813958,40.0298881530762,1.99695573893083,15.1699995622039,0.01373707364807,0.00230947025783455,0.25,-9.58484047277885E-6,0.00119167028879605,-8.81164085453266E-6,299.9140625,299.9140625,8921.611328125,8962.0908203125,47.9685422251974,17.2425410399582,,0,0,0,80,299.913208007812,1,6,1,1.923828125,63.0498542785645,,,,,,,,,,,,,,,,
,3931696331.428,299.914291381836,8382.1748046875,0.0012011794007475,8.11788463550002E-7,1,1.99850670813958,40.0298881530762,1.99678423261722,15.1699995622039,0.0138475450945739,0.00231427554798381,0.25,-1.08227602119062E-5,0.00120114937690916,-1.00433416636423E-5,299.915649414063,299.915649414063,8363.158203125,8401.19140625,47.4081145769089,17.2580317543581,,0,0,0,80,299.912933349609,1,6,1,1.92794799804687,62.5610961914062,,,,,,,,,,,,,,,,
,3931696359.434,299.914276123047,7825.6689453125,0.00121859247259305,9.56785433527957E-7,1,1.99850670813958,40.0298881530762,1.99673562011245,15.1699995622039,0.014048599265957,0.00234413109156829,0.25,-1.12958072821688E-5,0.00121856221578011,-1.05050450608795E-5,299.915069580078,299.915069580078,7805.42724609375,7845.91064453125,47.9271159136781,17.244900754042,,0,0,0,80,299.913482666016,1,6,1,1.92962646484375,63.0498542785645,,,,,,,,,,,,,,,,
,3931696387.441,299.913848876953,7269.71948242188,0.00123124387209304,8.09813310958724E-7,1,1.99850670813958,40.0298881530762,1.99640864789463,15.1699995622039,0.0141952531433437,0.00235081292927861,0.25,-1.29146943439286E-5,0.00123121428429019,-1.21156401469753E-5,299.914764404297,299.914764404297,7252.19873046875,7287.240234375,47.8606774895435,17.2522557881039,,0,0,0,80,299.912933349609,1,6,1,1.9281005859375,63.0498542785645,,,,,,,,,,,,,,,,
,3931696415.3575,299.914337158203,6711.6484375,0.00124074815789142,7.33991765183574E-7,1,1.99850670813958,40.0298881530762,1.99647086035169,15.1699995622039,0.0142984206915979,0.00240780549598799,0.25,-9.64512163650732E-6,0.00124071613877381,-8.83997005508603E-6,299.914337158203,299.914337158203,6692.5419921875,6730.7548828125,48.3179301732936,17.2551439459373,,0,0,0,80,299.914337158203,1,6,1,1.9189453125,63.5386123657227,,,,,,,,,,,,,,,,
,3931696443.3585,299.914566040039,6155.21459960937,0.00125281866975568,8.28871824451216E-7,1,1.99850670813958,40.0298881530762,1.99652741944638,15.1699995622039,0.0144373451036348,0.00243453746544807,0.25,-9.45734566415081E-6,0.0012527861465378,-8.64433632658384E-6,299.913787841797,299.913787841797,6135.3623046875,6175.06689453125,47.8184695495051,17.256482872665,,0,0,0,80,299.915344238281,1,6,1,1.92611694335938,63.5386123657227,,,,,,,,,,,,,,,,
,3931696471.342,299.914703369141,5602.40234375,0.00126290730289436,6.93594423742795E-7,1,1.99850670813958,40.0298881530762,1.99632112945095,15.1699995622039,0.0145508004866463,0.00246155774084328,0.25,-8.86782057279602E-6,0.00126287407869461,-8.04825151341224E-6,299.914764404297,299.914764404297,5582.09228515625,5622.71240234375,47.4190573761781,17.2626338515918,,0,0,0,80,299.914642333984,1,6,1,1.929931640625,64.0273742675781,,,,,,,,,,,,,,,,
,3931696499.335,299.913848876953,5043.33276367188,0.00127220648855412,7.90693603862035E-7,1,1.99850670813958,40.0298881530762,1.99625443547419,15.1699995622039,0.0146573028946671,0.00248054768640321,0.25,-8.85105180579398E-6,0.0012721729887178,-8.02541422790096E-6,299.913635253906,299.913635253906,5023.1240234375,5063.54150390625,47.5050365132935,17.2578221710231,,0,0,0,80,299.9140625,1,6,1,1.9244384765625,64.0273742675781,,,,,,,,,,,,,,,,
,3931696527.3275,299.914413452148,4487.91870117188,0.00128016313859184,7.32578815242146E-7,1,1.99850670813958,40.0298881530762,1.99618670408989,15.1699995622039,0.0147463059744692,0.00250835415645521,0.25,-7.83101951799713E-6,0.00128012871151635,-7.00022022445782E-6,299.914764404297,299.914764404297,4467.83740234375,4508,48.0029338800435,17.2471437938267,,0,0,0,80,299.9140625,1,6,1,1.91787719726562,64.0273742675781,,,,,,,,,,,,,,,,
,3931696555.263,299.914489746094,3930.91430664063,0.00128585520918637,7.4672299858791E-7,1,1.99850670813958,40.0298881530762,1.99588282303989,15.1699995622039,0.0148099127924702,0.00251789512123326,0.25,-7.97376709911079E-6,0.00128582069367717,-7.13923831518297E-6,299.914764404297,299.914764404297,3913.3349609375,3948.49365234375,47.5620953951973,17.2602332120161,,0,0,0,80,299.914215087891,1,6,1,1.92367553710938,64.0273742675781,,,,,,,,,,,,,,,,
,3931696583.2665,299.914413452148,3372.35705566406,0.00128990326381461,6.79117187723197E-7,1,1.99850670813958,40.0298881530762,1.99592707550882,15.1699995622039,0.014855864983381,0.00253148762498624,0.25,-7.51115062316624E-6,0.00128986832247776,-6.67397779544186E-6,299.915344238281,299.915344238281,3351.94995117188,3392.76416015625,48.1029823305051,17.2575630534284,,0,0,0,80,299.913482666016,1,6,1,1.92337036132813,63.5386123657227,,,,,,,,,,,,,,,,
,3931696611.224,299.914855957031,2816.09350585938,0.00129269565160551,6.99801020564194E-7,1,1.99850670813958,40.0298881530762,1.99584965921023,15.1699995622039,0.0148908379989499,0.00251776081723912,0.25,-9.18864673603806E-6,0.00129266169623681,-8.34958113993486E-6,299.915924072266,299.915924072266,2795.92260742187,2836.26440429687,47.9607259400051,17.2660836525014,,0,0,0,80,299.913787841797,1,6,1,1.91818237304687,64.5161285400391,,,,,,,,,,,,,,,,
,3931696639.1995,299.914566040039,2261.70666503906,0.00128716549371905,6.5015154443831E-7,1,1.99850670813958,40.0298881530762,1.99590593478363,15.1699995622039,0.0148259373815832,0.00251613818177938,0.25,-8.36015118620532E-6,0.00128713117749537,-7.52466943708973E-6,299.915344238281,299.915344238281,2241.42016601562,2281.9931640625,48.0607743904666,17.25968126757,,0,0,0,80,299.914215087891,1,6,1,1.92214965820313,64.5161285400391,,,,,,,,,,,,,,,,
,3931696667.1915,299.915145874023,1703.48669433594,0.00127651219809835,7.40092544830984E-7,1,1.99850670813958,40.0298881530762,1.99577728785995,15.1699995622039,0.0146968927958138,0.00252588653357611,0.25,-5.61993142691003E-6,0.00127647641270312,-4.79142119970903E-6,299.915649414063,299.915649414063,1683.42443847656,1723.54895019531,47.8559877184281,17.2622120632766,,0,0,0,80,299.913208007812,1,6,1,1.92230224609375,64.5161285400391,,,,,,,,,,,,,,,,
,3931696695.143,299.915557861328,1147.83239746094,0.00124831275581169,7.0531715330422E-7,1,1.99850670813958,40.0298881530762,1.99592328596467,15.1699995622039,0.0143732679932608,0.00247010151804088,0.25,-5.50973547464176E-6,0.00124827775552887,-4.69950349531688E-6,299.916778564453,299.916778564453,1127.83618164062,1167.82861328125,47.4081145769089,17.2615726639358,,0,0,0,80,299.914764404297,1,6,1,1.92276000976562,64.5161285400391,,,,,,,,,,,,,,,,
,3931696723.1505,299.91535949707,592.402313232422,0.0011793299109624,6.39437379089656E-7,1,1.99850670813958,40.0298881530762,1.99611407402275,15.1699995622039,0.0135825123254206,0.00232095512690812,0.25,-6.32311658913817E-6,0.00117929757362704,-5.5576020703013E-6,299.91650390625,299.91650390625,572.233825683594,612.57080078125,48.0091869081974,17.2486455265956,,0,0,0,80,299.913482666016,1,6,1,1.92398071289062,65.0048904418945,,,,,,,,,,,,,,,,
,3931696751.1405,299.914779663086,32.9526515007019,0.000811850417973838,2.72019144521272E-6,1,1.99850670813958,40.0298881530762,1.99555263888981,15.1699995622039,0.00934506646989734,0.00161199102533551,0.25,-3.07663069595183E-6,0.000811827338624491,-2.54967709664736E-6,299.915496826172,299.915496826172,12.8832883834839,53.0220146179199,47.7629739246397,17.2713723458895,,0,0,0,80,299.914642333984,1,6,1,1.91024780273438,65.0048904418945,,,,,,,,,,,,,,,,
,3931696779.104,299.915496826172,-522.4609375,-0.00115571754499688,6.65619930446032E-7,1,1.99850670813958,40.0298881530762,1.99575441558219,15.1699995622039,-0.0133048546578398,-0.00229332020074793,0.25,4.52487352637094E-6,-0.00115568476636276,3.77473563341435E-6,299.915924072266,299.915924072266,-541.392639160156,-503.529235839844,47.3541822090819,17.2643083581442,,0,0,0,80,299.913208007812,1,6,1,1.92337036132813,65.0048904418945,,,,,,,,,,,,,,,,
,3931696807.069,299.91520690918,-1078.80206298828,-0.00123981317059902,7.1182136772919E-7,1,1.99850670813958,40.0298881530762,1.99565977759635,15.1699995622039,-0.0142715620483272,-0.00246441379525056,0.25,4.4774245375278E-6,-0.00123977777296362,3.67273600510585E-6,299.916625976562,299.916625976562,-1099.03430175781,-1058.56982421875,48.0693723041782,17.2686310948372,,0,0,0,80,299.914642333984,1,6,1,1.920166015625,65.0048904418945,,,,,,,,,,,,,,,,
,3931696835.041,299.915634155273,-1634.87670898438,-0.00127267981654219,7.54836240187363E-7,1,1.99850670813958,40.0298881530762,1.99552494624345,15.1699995622039,-0.0146511045626554,-0.00251727989147837,0.25,5.66526541829216E-6,-0.00127264416409826,4.83923890416792E-6,299.91650390625,299.91650390625,-1655.04284667969,-1614.71057128906,47.7434332116589,17.2736106948988,,0,0,0,80,299.913635253906,1,6,1,1.92764282226562,65.0048904418945,,,,,,,,,,,,,,,,
,3931696863.073,299.914489746094,-2192.81335449219,-0.00128599706491153,5.53403942155413E-7,1,1.99850670813958,40.0298881530762,1.99574419491812,15.1699995622039,-0.0148094708383591,-0.00252413331821001,0.25,7.44193532137571E-6,-0.00128596219090243,6.60723633359126E-6,299.915344238281,299.915344238281,-2211.77807617187,-2173.8486328125,47.8849079736397,17.2642060217733,,0,0,0,80,299.914764404297,1,6,1,1.93679809570313,65.0048904418945,,,,,,,,,,,,,,,,
,3931696891.0085,299.91584777832,-2749.95239257813,-0.0012893546588662,5.16760106793025E-7,1,1.99850670813958,40.0298881530762,1.99561019350541,15.1699995622039,-0.01484565725776,-0.00253914937585566,0.25,6.71458592168324E-6,-0.00128931917108999,5.87776416075648E-6,299.916625976562,299.916625976562,-2770.00048828125,-2729.904296875,48.0928211597551,17.2642816609636,,0,0,0,80,299.915069580078,1,6,1,1.9189453125,65.4936447143555,,,,,,,,,,,,,,,,
,3931696919.023,299.915130615234,-3305.84033203125,-0.00129101225312886,7.31358971627183E-7,1,1.99850670813958,40.0298881530762,1.99543158669723,15.1699995622039,-0.0148630703683562,-0.00254438613728521,0.25,6.53259283377311E-6,-0.00129097662062321,5.6947292259058E-6,299.915924072266,299.915924072266,-3325.98999023438,-3285.69067382812,47.7872044087358,17.2722523090159,,0,0,0,80,299.914215087891,1,6,1,1.92901611328125,65.4936447143555,,,,,,,,,,,,,,,,
,3931696946.996,299.914993286133,-3862.01391601562,-0.00128659627413133,8.44164392453754E-7,1,1.99850670813958,40.0298881530762,1.99520362078895,15.1699995622039,-0.0148108943425056,-0.00253370429628897,0.25,6.65790710393822E-6,-0.0012865608664667,5.82293576782042E-6,299.916198730469,299.916198730469,-3882.07861328125,-3841.94921875,47.7950206939281,17.2690573782514,,0,0,0,80,299.913787841797,1,6,1,1.92642211914062,65.4936447143555,,,,,,,,,,,,,,,,
,3931696974.978,299.915420532227,-4420.44384765625,-0.00127965112996466,7.09393165200861E-7,1,1.99850670813958,40.0298881530762,1.99578976070099,15.1699995622039,-0.0147361331572022,-0.00251503959922867,0.25,7.11766971037262E-6,-0.00127961622535674,6.28722382582946E-6,299.916076660156,299.916076660156,-4440.85791015625,-4400.02978515625,47.9153914858897,17.2615883234254,,0,0,0,80,299.914764404297,1,6,1,1.91848754882813,65.0048904418945,,,,,,,,,,,,,,,,
,3931697002.946,299.915496826172,-4977.2265625,-0.00127075619229133,7.64172032435538E-7,1,1.99850670813958,40.0298881530762,1.99589461511498,15.1699995622039,-0.0146379846690272,-0.00247761545698834,0.25,8.81250814061087E-6,-0.00127072266282736,7.98781378095711E-6,299.915924072266,299.915924072266,-4997.2109375,-4957.2421875,48.4437723648897,17.2524863947306,,0,0,0,80,299.915069580078,1,6,1,1.91253662109375,65.4936447143555,,,,,,,,,,,,,,,,
,3931697030.9335,299.915634155273,-5534.2216796875,-0.0012621655651739,6.68558577929496E-7,1,1.99850670813958,40.0298881530762,1.99539429962988,15.1699995622039,-0.0145374116694371,-0.00244946289675738,0.25,9.69245253819231E-6,-0.0012621328709672,8.87333792496439E-6,299.91650390625,299.91650390625,-5552.94580078125,-5515.49755859375,47.6746499019666,17.2770051205742,,0,0,0,80,299.914764404297,1,6,1,1.9110107421875,65.4936447143555,,,,,,,,,,,,,,,,
,3931697058.919,299.915420532227,-6090.85546875,-0.00125235762779817,6.98478232218863E-7,1,1.99850670813958,40.0298881530762,1.99559319263557,15.1699995622039,-0.0144239970617149,-0.00244108440028327,0.25,8.71115783410313E-6,-0.00125232460934283,7.89846926279213E-6,299.915924072266,299.915924072266,-6111.16796875,-6070.54296875,48.1561330698128,17.2674852595141,,0,0,0,80,299.914916992188,1,6,1,1.91619873046875,65.4936447143555,,,,,,,,,,,,,,,,
,3931697086.871,299.914764404297,-6646.67944335938,-0.00124051962489001,7.44037308702537E-7,1,1.99850670813958,40.0298881530762,1.99546207022256,15.1699995622039,-0.0142844291318769,-0.00243099014205576,0.25,7.48697411831245E-6,-0.00124048620008772,6.68203465693272E-6,299.914764404297,299.914764404297,-6666.7607421875,-6626.59814453125,48.0162215648705,17.2658435946746,,0,0,0,80,299.914764404297,1,6,1,1.93557739257813,65.4936447143555,,,,,,,,,,,,,,,,
,3931697114.867,299.914566040039,-7203.79248046875,-0.00122943740753198,8.41655186004471E-7,1,1.99850670813958,40.0298881530762,1.99558206602004,15.1699995622039,-0.0141585057155688,-0.0024045154046792,0.25,7.84580142677898E-6,-0.00122940456644212,7.04807336427836E-6,299.914916992188,299.914916992188,-7223.9111328125,-7183.673828125,47.9779217674281,17.2668265048062,,0,0,0,80,299.914215087891,1,6,1,1.9097900390625,65.4936447143555,,,,,,,,,,,,,,,,
,3931697142.8215,299.91535949707,-7759.11865234375,-0.00121921776051496,8.65289789239878E-7,1,1.99850670813958,40.0298881530762,1.99554806454209,15.1699995622039,-0.0140470448053457,-0.00234785310916846,0.25,1.09653859316611E-5,-0.00121918723880821,1.01742272997125E-5,299.915649414063,299.915649414063,-7779.36279296875,-7738.87451171875,48.0662457901012,17.2686210056689,,0,0,0,80,299.915069580078,1,6,1,1.92657470703125,65.4936447143555,,,,,,,,,,,,,,,,
,3931697170.8115,299.91535949707,-8315.58251953125,-0.00120370911923178,8.82214204426812E-7,1,1.99850670813958,40.0298881530762,1.99572441528341,15.1699995622039,-0.0138671028816868,-0.00233205235557527,0.25,9.62053456352976E-6,-0.00120367820714874,8.83951123473565E-6,299.915069580078,299.915069580078,-8335.6630859375,-8295.501953125,47.6801213016012,17.2620673284538,,0,0,0,80,299.915649414063,1,6,1,1.9293212890625,65.4936447143555,,,,,,,,,,,,,,,,
,3931697198.792,299.914916992188,-8871.427734375,-0.00119135052575741,9.01511652073067E-7,1,1.99850670813958,40.0298881530762,1.99553598214198,15.1699995622039,-0.0137226646321699,-0.00231249558541108,0.25,9.12207087759605E-6,-0.00119131968738417,8.34911195851675E-6,299.915496826172,299.915496826172,-8891.6669921875,-8851.1884765625,48.1553514412936,17.2608274188505,,0,0,0,80,299.914337158203,1,6,1,1.925048828125,65.4936447143555,,,,,,,,,,,,,,,,
,3931697226.7835,299.915573120117,-9427.90673828125,-0.00118041051478048,9.87213496010445E-7,1,1.99850670813958,40.0298881530762,1.99534248041246,15.1699995622039,-0.0135984276045066,-0.00227374973733828,0.25,1.05419861712096E-5,-0.00118038091992629,9.77611532474865E-6,299.916076660156,299.916076660156,-9448.001953125,-9407.8115234375,47.7262373842358,17.2687498393318,,0,0,0,80,299.915069580078,1,6,1,1.92626953125,65.9824066162109,,,,,,,,,,,,,,,,
,3931697254.74,299.915145874023,-9984.771484375,-0.00116515297667143,8.18699192480625E-7,1,1.99850670813958,40.0298881530762,1.99502103071247,15.1699995622039,-0.0134224437528701,-0.00223338478008741,0.25,1.13296637512494E-5,-0.00116512437838919,1.05736972111919E-5,299.915649414063,299.915649414063,-10004.7607421875,-9964.7822265625,47.9404035985051,17.2794035552896,,0,0,0,80,299.914642333984,1,6,1,1.93099975585938,65.9824066162109,,,,,,,,,,,,,,,,
,3931697282.762,299.91520690918,-10543.2436523438,-0.0011512715898114,8.93862186803886E-7,1,1.99850670813958,40.0298881530762,1.99533220219517,15.1699995622039,-0.013262549206213,-0.00221834551599945,0.25,1.02177609967563E-5,-0.00115124270026552,9.47086588875618E-6,299.915649414063,299.915649414063,-10563.5771484375,-10522.91015625,47.8020553506012,17.2710174969479,,0,0,0,80,299.914764404297,1,6,1,1.9281005859375,65.9824066162109,,,,,,,,,,,,,,,,
,3931697310.7465,299.91520690918,-11100.0737304688,-0.00113878899881057,9.41357975975264E-7,1,1.99850670813958,40.0298881530762,1.99504409402137,15.1699995622039,-0.0131157845230521,-0.00220042262015549,0.25,9.5473340465364E-6,-0.00113876006280019,8.80858895000682E-6,299.915649414063,299.915649414063,-11121.3232421875,-11078.82421875,47.3909187494858,17.2800920728523,,0,0,0,80,299.914764404297,1,6,1,1.91604614257813,65.4936447143555,,,,,,,,,,,,,,,,
,3931697338.688,299.915786743164,-11655.4755859375,-0.00112254348121738,9.87241991496251E-7,1,1.99850670813958,40.0298881530762,1.99551092553335,15.1699995622039,-0.0129329454117849,-0.00216191923016708,0.25,1.00721171593029E-5,-0.00112251537456045,9.34392620466749E-6,299.915649414063,299.915649414063,-11675.646484375,-11635.3046875,48.1115802442166,17.2613842890502,,0,0,0,80,299.916198730469,1,6,1,1.92840576171875,65.9824066162109,,,,,,,,,,,,,,,,
,3931697366.6765,299.914413452148,-12214.0659179688,-0.00111225887951838,1.11282511346407E-6,1,1.99850670813958,40.0298881530762,1.99559976140661,15.1699995622039,-0.0128171282702046,-0.00213018060348903,0.25,1.10250331779415E-5,-0.00111223174700313,1.03035125418975E-5,299.916625976562,299.916625976562,-12234.212890625,-12193.9189453125,48.2538366347166,17.2598229883657,,0,0,0,80,299.9140625,1,6,1,1.92245483398438,65.9824066162109,,,,,,,,,,,,,,,,
,3931697394.63,299.915283203125,-12771.23046875,-0.00109843370670176,1.19483653090738E-6,1,1.99850670813958,40.0298881530762,1.99515121591221,15.1699995622039,-0.0126547245544181,-0.0021051660884754,0.25,1.07209832115181E-5,-0.00109840678394514,1.00084726773318E-5,299.915496826172,299.915496826172,-12791.3115234375,-12751.1494140625,47.740306697582,17.2723000424713,,0,0,0,80,299.9140625,1,6,1,1.92535400390625,65.9824066162109,,,,,,,,,,,,,,,,
,3931697422.638,299.915710449219,-13328.41015625,-0.00107932912358602,9.90906128366515E-7,1,1.99850670813958,40.0298881530762,1.99551509475478,15.1699995622039,-0.0124363759258708,-0.00207142559778773,0.25,1.03163569319046E-5,-0.0010793025199773,9.61628063755174E-6,299.915924072266,299.915924072266,-13347.33984375,-13309.48046875,47.9411852270243,17.2652180671446,,0,0,0,80,299.915496826172,1,6,1,1.91558837890625,65.9824066162109,,,,,,,,,,,,,,,,
,3931697450.611,299.915069580078,-13884.630859375,-0.00106811680852632,1.16819209189645E-6,1,1.99850670813958,40.0298881530762,1.99555244170545,15.1699995622039,-0.0123089121916837,-0.00204141098172182,0.25,1.09509800932669E-5,-0.00106809098131669,1.02581857823005E-5,299.917205810547,299.917205810547,-13904.8017578125,-13864.4599609375,48.2577447773128,17.2588992821537,,0,0,0,80,299.912933349609,1,6,1,1.91787719726562,65.9824066162109,,,,,,,,,,,,,,,,
,3931697478.5735,299.914566040039,-14440.7734375,-0.0010520470620518,9.80920946109842E-7,1,1.99850670813958,40.0298881530762,1.99508985250386,15.1699995622039,-0.0121193579588298,-0.00201960656624996,0.25,9.97240358269113E-6,-0.00105202111130553,9.29008981649748E-6,299.915649414063,299.915649414063,-14460.8623046875,-14420.6845703125,47.9161731144089,17.2749686407341,,0,0,0,80,299.914337158203,1,6,1,1.91299438476562,65.9824066162109,,,,,,,,,,,,,,,,
,3931697506.573,299.915649414063,-14989.6420898438,-0.00104084085549374,2.22285857728453E-6,1,1.99850670813958,40.0298881530762,1.99529572316083,15.1699995622039,-0.0119905036882437,-0.00200371797926152,0.25,9.39450743703734E-6,-0.00104081485207807,8.71951185587546E-6,299.915649414063,299.915649414063,-14999.84765625,-14979.4365234375,48.2124103231974,17.2739780163276,,0,0,0,80,299.915649414063,1,4,1,1.91375732421875,65.9824066162109,,,,,,,,,,,,,,,,
,3931697540.543,299.914001464844,-14512.0268554687,-0.00104914166089748,8.66467354790784E-7,1,1.99850670813958,40.0298881530762,1.99536690635081,15.1699995622039,-0.012093934038342,-0.00197788733888649,0.25,1.31105550094931E-5,-0.00104911784827773,1.24300309940155E-5,299.912933349609,299.912933349609,-14532.2353515625,-14491.818359375,47.6300970763704,17.2632678890369,,0,0,0,80,299.9140625,1,6,1,1.91650390625,65.9824066162109,,,,,,,,,,,,,,,,
,3931697568.497,299.915283203125,-13954.7749023437,-0.00106509184870371,1.10362502768308E-6,1,1.99850670813958,40.0298881530762,1.99496329748626,15.1699995622039,-0.0122733365495262,-0.00201925092235123,0.25,1.22936948207271E-5,-0.0010650669802819,1.1602824997956E-5,299.914916992188,299.914916992188,-13974.9345703125,-13934.615234375,48.2639978054666,17.276009344712,,0,0,0,80,299.915496826172,1,6,1,1.93923950195313,65.9824066162109,,,,,,,,,,,,,,,,
,3931697596.5205,299.914932250977,-13398.0092773437,-0.00108058127382455,9.5232629027367E-7,1,1.99850670813958,40.0298881530762,1.99508933580294,15.1699995622039,-0.0124524556383589,-0.00204947979199087,0.25,1.2408329622019E-5,-0.00108055600794062,1.17073793379991E-5,299.914215087891,299.914215087891,-13418.15625,-13377.8623046875,48.373425798159,17.2724421018994,,0,0,0,80,299.914764404297,1,6,1,1.91207885742187,65.9824066162109,,,,,,,,,,,,,,,,
,3931697624.503,299.915267944336,-12841.3618164062,-0.00109724453233471,1.00587463305144E-6,1,1.99850670813958,40.0298881530762,1.99515449937322,15.1699995622039,-0.012645641227347,-0.00207683224110608,0.25,1.29751153984748E-5,-0.00109721910851909,1.22633106653699E-5,299.914337158203,299.914337158203,-12860.462890625,-12822.2607421875,47.8106532643128,17.2742980851463,,0,0,0,80,299.914764404297,1,6,1,1.91574096679687,65.9824066162109,,,,,,,,,,,,,,,,
,3931697652.4485,299.914855957031,-12285.1381835938,-0.0011081379457027,1.1506098720093E-6,1,1.99850670813958,40.0298881530762,1.99495036974174,15.1699995622039,-0.0127621271411568,-0.00214144193627736,0.25,9.26055535438126E-6,-0.001108109785062,8.54176665429355E-6,299.914642333984,299.914642333984,-12305.3798828125,-12264.896484375,47.6668336167743,17.2775823297263,,0,0,0,80,299.914337158203,1,6,1,1.92535400390625,65.9824066162109,,,,,,,,,,,,,,,,
,3931697680.461,299.914566040039,-11727.9897460938,-0.00112554329608432,1.08588419854254E-6,1,1.99850670813958,40.0298881530762,1.99539081368734,15.1699995622039,-0.0129691167625447,-0.00215416767043222,0.25,1.12642734052193E-5,-0.00112551590244642,1.05341018295373E-5,299.913787841797,299.913787841797,-11748.068359375,-11707.9111328125,48.0162215648705,17.2771097397186,,0,0,0,80,299.914337158203,1,6,1,1.92428588867187,66.4711685180664,,,,,,,,,,,,,,,,
,3931697708.399,299.914489746094,-11172.0717773438,-0.00113682865351317,1.02198562640434E-6,1,1.99850670813958,40.0298881530762,1.99526901721887,15.1699995622039,-0.0131016582037605,-0.00215705341345906,0.25,1.29931040160787E-5,-0.00113680203187477,1.22555264323958E-5,299.9140625,299.9140625,-11191.990234375,-11152.1533203125,47.557405624082,17.2710851168189,,0,0,0,80,299.914916992188,1,6,1,1.91131591796875,65.9824066162109,,,,,,,,,,,,,,,,
,3931697736.3845,299.914703369141,-10614.689453125,-0.00114807681157192,1.03513812091596E-6,1,1.99850670813958,40.0298881530762,1.99514068972766,15.1699995622039,-0.0132252290246993,-0.00220795763555851,0.25,1.05395304122762E-5,-0.0011480482431812,9.794700226638E-6,299.914764404297,299.914764404297,-10634.8388671875,-10594.5400390625,47.8309756058127,17.2766657130458,,0,0,0,80,299.914642333984,1,6,1,1.9146728515625,66.4711685180664,,,,,,,,,,,,,,,,
,3931697764.353,299.915496826172,-10057.2866210938,-0.00116272672981452,9.56343986092872E-7,1,1.99850670813958,40.0298881530762,1.99520106244821,15.1699995622039,-0.0133915113671371,-0.00225245788858104,0.25,9.26024220840146E-6,-0.00116269685521374,8.50591846762143E-6,299.915924072266,299.915924072266,-10077.533203125,-10037.0400390625,47.8481714332358,17.2783438639528,,0,0,0,80,299.915069580078,1,6,1,1.91238403320313,65.9824066162109,,,,,,,,,,,,,,,,
,3931697792.3465,299.914764404297,-9500.41162109375,-0.00117482679927403,8.80848168459401E-7,1,1.99850670813958,40.0298881530762,1.99538101655946,15.1699995622039,-0.0135316885957953,-0.00227815583081988,0.25,9.17763932973692E-6,-0.00117479651456845,8.41543411517294E-6,299.914764404297,299.914764404297,-9519.30078125,-9481.5224609375,48.0685906756589,17.2625415812493,,0,0,0,80,299.914764404297,1,6,1,1.92352294921875,66.4711685180664,,,,,,,,,,,,,,,,
,3931697820.3325,299.915069580078,-8944.650390625,-0.0011895322088623,8.67398742246241E-7,1,1.99850670813958,40.0298881530762,1.99544139807093,15.1699995622039,-0.0137023607835004,-0.00230166991632471,0.25,9.73325779201874E-6,-0.00118950181916586,8.96146433090894E-6,299.9140625,299.9140625,-8964.7080078125,-8924.5927734375,48.0693723041782,17.2634724073136,,0,0,0,80,299.916076660156,1,6,1,1.92611694335938,65.9824066162109,,,,,,,,,,,,,,,,
,3931697848.309,299.91520690918,-8388.06396484375,-0.00120344105235538,8.07482923443381E-7,1,1.99850670813958,40.0298881530762,1.99512912490137,15.1699995622039,-0.0138607465882867,-0.00232672602661537,0.25,9.97790485363013E-6,-0.00120341038505406,9.19704844457658E-6,299.915496826172,299.915496826172,-8408.19921875,-8367.9287109375,47.8247225776589,17.2720007647821,,0,0,0,80,299.914916992188,1,6,1,1.90826416015625,65.9824066162109,,,,,,,,,,,,,,,,
,3931697876.3155,299.915420532227,-7831.85278320312,-0.00121592030456062,9.6389318795488E-7,1,1.99850670813958,40.0298881530762,1.99535336875814,15.1699995622039,-0.0140014099102605,-0.00237712394293837,0.25,7.81961276743174E-6,-0.00121588784289176,7.03069476195253E-6,299.914916992188,299.914916992188,-7851.771484375,-7811.93408203125,48.0904762741974,17.2621323177555,,0,0,0,80,299.915924072266,1,6,1,1.92398071289062,66.4711685180664,,,,,,,,,,,,,,,,
,3931697904.2635,299.914566040039,-7275.3955078125,-0.00122670702684605,7.03007645945578E-7,1,1.99850670813958,40.0298881530762,1.99536584679915,15.1699995622039,-0.0141289819164361,-0.00237965244795378,0.25,9.5038626437713E-6,-0.00122667534592494,8.70785893663321E-6,299.9140625,299.9140625,-7295.39404296875,-7255.39697265625,48.2241347509859,17.2685789008228,,0,0,0,80,299.915069580078,1,6,1,1.92611694335938,66.4711685180664,,,,,,,,,,,,,,,,
,3931697932.2675,299.914215087891,-6716.17041015625,-0.00123768095220858,6.11672898528078E-7,1,1.99850670813958,40.0298881530762,1.99532489912754,15.1699995622039,-0.0142547196653988,-0.0024030195871354,0.25,9.40401252141222E-6,-0.00123764887486771,8.6008579418243E-6,299.912933349609,299.912933349609,-6736.435546875,-6695.9052734375,48.0302908782166,17.2656841745662,,0,0,0,80,299.915496826172,1,6,1,1.92352294921875,66.4711685180664,,,,,,,,,,,,,,,,
,3931697960.215,299.91535949707,-6161.33520507812,-0.00125192809883661,8.47680263278499E-7,1,1.99850670813958,40.0298881530762,1.99501079989376,15.1699995622039,-0.014415465059171,-0.00243682164177639,0.25,8.94617311436094E-6,-0.00125189524829437,8.13376004026006E-6,299.915069580078,299.915069580078,-6180.06884765625,-6142.6015625,47.6105563633897,17.2842905667652,,0,0,0,80,299.915649414063,1,6,1,1.91619873046875,65.9824066162109,,,,,,,,,,,,,,,,
,3931697988.224,299.914764404297,-5603.3466796875,-0.00126163331624613,7.9336618947165E-7,1,1.99850670813958,40.0298881530762,1.99514876041383,15.1699995622039,-0.0145263581565501,-0.00246625061988635,0.25,8.11354214369119E-6,-0.00126159964024095,7.29482309037794E-6,299.914764404297,299.914764404297,-5623.41845703125,-5583.27490234375,47.7160762134858,17.2694557275453,,0,0,0,80,299.914764404297,1,6,1,1.92489624023438,66.4711685180664,,,,,,,,,,,,,,,,
,3931698016.166,299.914413452148,-5048.8916015625,-0.00127238201275036,7.29772360022339E-7,1,1.99850670813958,40.0298881530762,1.99491888650663,15.1699995622039,-0.0146472469624673,-0.00249401085998718,0.25,7.57175716158235E-6,-0.0012723476607668,6.7460472527815E-6,299.9140625,299.9140625,-5069.30322265625,-5028.47998046875,48.0240378500628,17.2754128419683,,0,0,0,80,299.914764404297,1,6,1,1.923828125,66.4711685180664,,,,,,,,,,,,,,,,
,3931698044.164,299.914764404297,-4491.35815429687,-0.00127883354141446,7.28825556525314E-7,1,1.99850670813958,40.0298881530762,1.99491477401841,15.1699995622039,-0.0147219296517207,-0.00250413293076385,0.25,7.82919991021614E-6,-0.00127879914371362,6.9992645964805E-6,299.914764404297,299.914764404297,-4510.32080078125,-4472.3955078125,48.3148036592167,17.2768085037189,,0,0,0,80,299.914764404297,1,6,1,1.91207885742187,66.4711685180664,,,,,,,,,,,,,,,,
,3931698072.1275,299.914642333984,-3935.84765625,-0.00128556641377126,7.92674477825596E-7,1,1.99850670813958,40.0298881530762,1.99524408067632,15.1699995622039,-0.0147988835580943,-0.00253425177414158,0.25,6.43295465211432E-6,-0.00128553090291288,5.59866156691111E-6,299.914215087891,299.914215087891,-3955.90283203125,-3915.79248046875,48.0365439063705,17.2690009004428,,0,0,0,80,299.914764404297,1,6,1,1.92825317382813,65.9824066162109,,,,,,,,,,,,,,,,
,3931698100.101,299.91520690918,-3378.40209960937,-0.00129149271060188,7.65122366119639E-7,1,1.99850670813958,40.0298881530762,1.9947941223572,15.1699995622039,-0.0148664191937177,-0.00253088979947302,0.25,7.72271517280527E-6,-0.00129145783354035,6.88450735355107E-6,299.914764404297,299.914764404297,-3398.4169921875,-3358.38720703125,47.8919426303128,17.2787056919403,,0,0,0,80,299.916076660156,1,6,1,1.9146728515625,66.4711685180664,,,,,,,,,,,,,,,,
,3931698128.1145,299.914215087891,-2819.67248535156,-0.00129191337559273,5.93910232997014E-7,1,1.99850670813958,40.0298881530762,1.99525770529883,15.1699995622039,-0.0148734012681565,-0.00253909349228333,0.25,7.13312183884736E-6,-0.00129187813000935,6.29462547110755E-6,299.912933349609,299.912933349609,-2839.845703125,-2799.49926757813,47.8341021198897,17.2682644802609,,0,0,0,80,299.915496826172,1,6,1,1.92611694335938,66.4711685180664,,,,,,,,,,,,,,,,
,3931698156.078,299.915344238281,-2262.83544921875,-0.00128792193750767,7.71600080179465E-7,1,1.99850670813958,40.0298881530762,1.99522348186633,15.1699995622039,-0.0148251648526477,-0.00254275966664142,0.25,6.10662385467109E-6,-0.00128788611221367,5.27072336766654E-6,299.914764404297,299.914764404297,-2282.83642578125,-2242.83447265625,48.1647309835243,17.2669711425356,,0,0,0,80,299.915924072266,1,6,1,1.92733764648438,66.4711685180664,,,,,,,,,,,,,,,,
,3931698184.0845,299.91520690918,-1705.64703369141,-0.00127779865632936,6.81791669510878E-7,1,1.99850670813958,40.0298881530762,1.99526412786769,15.1699995622039,-0.0147107039940565,-0.0025127450096435,0.25,6.93486922417212E-6,-0.00127776368265193,6.10548388241843E-6,299.914337158203,299.914337158203,-1725.78015136719,-1685.51391601562,48.1842716965051,17.2667589025264,,0,0,0,80,299.916076660156,1,6,1,1.92520141601562,66.4711685180664,,,,,,,,,,,,,,,,
,3931698212.067,299.91535949707,-1147.85418701172,-0.00124901678394362,5.9374662319599E-7,1,1.99850670813958,40.0298881530762,1.99525837241452,15.1699995622039,-0.0143776851166645,-0.00246535916942315,0.25,5.97709431828033E-6,-0.00124898207097989,5.16639042473864E-6,299.914215087891,299.914215087891,-1167.94482421875,-1127.76354980469,48.3155852877359,17.2671382806248,,0,0,0,80,299.914916992188,1,6,1,1.925048828125,66.4711685180664,,,,,,,,,,,,,,,,
,3931698240.012,299.914642333984,-593.448364257812,-0.00118212788344661,7.10338709614934E-7,1,1.99850670813958,40.0298881530762,1.99496040132459,15.1699995622039,-0.0136036755735787,-0.0023447494910773,0.25,4.63482656887892E-6,-0.00118209438387736,3.8675464192954E-6,299.913635253906,299.913635253906,-612.304565429688,-574.592163085937,48.2366408072936,17.2759724678399,,0,0,0,80,299.915344238281,1,6,1,1.91818237304687,66.4711685180664,,,,,,,,,,,,,,,,
,3931698267.995,299.914199829102,-36.4038333892822,-0.000817892857165093,2.79092896893427E-6,1,1.99850670813958,40.0298881530762,1.99522104036987,15.1699995622039,-0.00941206255408249,-0.00162965326145826,0.25,2.58434058441272E-6,-0.000817869282797116,2.05347974947518E-6,299.9140625,299.9140625,-55.5644912719727,-17.2431755065918,48.0560846193512,17.2667455819134,,0,0,0,80,299.916076660156,1,6,1,1.92459106445313,65.9824066162109,,,,,,,,,,,,,,,,
,3931698295.9815,299.915069580078,519.016845703125,0.00115718954980646,7.71157557441094E-7,1,1.99850670813958,40.0298881530762,1.99514577303842,15.1699995622039,0.0133200656013904,0.00228313776406317,0.25,-5.6111191148746E-6,0.00115715744214829,-4.85999106507666E-6,299.915069580078,299.915069580078,501.5107421875,536.52294921875,48.1373739853512,17.2709325442152,,0,0,0,80,299.915649414063,1,6,1,1.92596435546875,66.4711685180664,,,,,,,,,,,,,,,,
,3931698323.962,299.916213989258,1074.98510742188,0.00123997006808942,5.78073111290659E-7,1,1.99850670813958,40.0298881530762,1.99522516946407,15.1699995622039,0.0142746352787031,0.00243998778015094,0.25,-6.58374567887493E-6,0.00123993600323836,-5.77889315953185E-6,299.915924072266,299.915924072266,1054.82836914062,1095.14184570312,48.0459234486012,17.2678074775842,,0,0,0,80,299.913055419922,1,6,1,1.91390991210938,66.9599227905273,,,,,,,,,,,,,,,,
,3931698351.9595,299.915069580078,1633.97454833984,0.00127192359956061,6.86318685758944E-7,1,1.99850670813958,40.0298881530762,1.99490944043123,15.1699995622039,0.0146381904347711,0.00251414361184066,0.25,-5.73933453950399E-6,0.00127188803533813,-4.9137946328623E-6,299.914215087891,299.914215087891,1613.72583007813,1654.22326660156,47.5425546822166,17.2806156750306,,0,0,0,80,299.914764404297,1,6,1,1.917724609375,66.4711685180664,,,,,,,,,,,,,,,,
,3931698379.916,299.914566040039,2189.29125976562,0.00128536392731646,6.91108215299309E-7,1,1.99850670813958,40.0298881530762,1.99517966102077,15.1699995622039,0.0147945402579894,0.00254256301095697,0.25,-5.66780268194081E-6,0.00128532791932873,-4.83356936662281E-6,299.913482666016,299.913482666016,2169.05444335938,2209.52807617187,47.821596063582,17.2653099438024,,0,0,0,80,299.914764404297,1,6,1,1.91375732421875,66.4711685180664,,,,,,,,,,,,,,,,
,3931698407.885,299.914993286133,2748.30676269531,0.00129036064360585,7.27864176521379E-7,1,1.99850670813958,40.0298881530762,1.99524559219413,15.1699995622039,0.0148571690723296,0.00252621182948554,0.25,-7.97792549651098E-6,0.00129032597025693,-7.14040917790924E-6,299.9140625,299.9140625,2728.2255859375,2768.38793945313,48.261652919909,17.2664188937814,,0,0,0,80,299.915069580078,1,6,1,1.9134521484375,66.4711685180664,,,,,,,,,,,,,,,,
,3931698435.8665,299.91520690918,3305.2900390625,0.00128944896177783,6.7571958160809E-7,1,1.99850670813958,40.0298881530762,1.99511444139294,15.1699995622039,0.0148439943622444,0.00253409770677683,0.25,-7.1174274986869E-6,0.0012894137547133,-6.28056036706675E-6,299.914337158203,299.914337158203,3285.04125976562,3325.53881835937,48.1514432986974,17.2711172897141,,0,0,0,80,299.915924072266,1,6,1,1.91360473632813,66.4711685180664,,,,,,,,,,,,,,,,
,3931698463.8545,299.915130615234,3860.16064453125,0.00128665201253597,6.88296241872088E-7,1,1.99850670813958,40.0298881530762,1.99515872670802,15.1699995622039,0.0148152160273764,0.00251107058498386,0.25,-8.63093472863364E-6,0.00128661787914135,-7.79586662723448E-6,299.914764404297,299.914764404297,3840.16674804687,3880.15454101562,47.8489530617551,17.2769939844797,,0,0,0,80,299.915649414063,1,6,1,1.91421508789062,66.4711685180664,,,,,,,,,,,,,,,,
,3931698491.8085,299.9140625,4418.99658203125,0.00127783151228798,6.41967281646903E-7,1,1.99850670813958,40.0298881530762,1.99522657826618,15.1699995622039,0.0147157744846186,0.00248465023236577,0.25,-9.3793007545888E-6,0.0012777981717914,-8.54996131150867E-6,299.913787841797,299.913787841797,4400.130859375,4437.8623046875,48.1788002968705,17.2675224541862,,0,0,0,80,299.914337158203,1,6,1,1.91421508789062,66.4711685180664,,,,,,,,,,,,,,,,
,3931698519.8035,299.915496826172,4975.47265625,0.00127091522611371,6.961409175748E-7,1,1.99850670813958,40.0298881530762,1.99518254468536,15.1699995622039,0.0146355428226115,0.00247267736226589,0.25,-9.19562832052414E-6,0.0012708819402832,-8.37081884863946E-6,299.915344238281,299.915344238281,4955.08203125,4995.86328125,48.177237039832,17.2675140100585,,0,0,0,80,299.915649414063,1,6,1,1.91680908203125,66.4711685180664,,,,,,,,,,,,,,,,
,3931698547.777,299.914215087891,5532.20288085937,0.00126198961767865,7.44824144111267E-7,1,1.99850670813958,40.0298881530762,1.9952754968021,15.1699995622039,0.0145349876635881,0.00244649415212009,0.25,-9.9072859988078E-6,0.00126195711016048,-9.08827448708382E-6,299.912933349609,299.912933349609,5512.11474609375,5552.291015625,47.5855442507743,17.2674747477155,,0,0,0,80,299.915496826172,1,6,1,1.91253662109375,66.4711685180664,,,,,,,,,,,,,,,,
,3931698575.7635,299.915924072266,6091.50390625,0.00125053034368638,7.53295938107384E-7,1,1.99850670813958,40.0298881530762,1.99519484872889,15.1699995622039,0.0144013667485522,0.00243027974271324,0.25,-9.28730657095586E-6,0.0012504977406808,-8.47578714351293E-6,299.915344238281,299.915344238281,6071.34716796875,6111.66064453125,48.1326842142359,17.2637834742062,,0,0,0,80,299.91650390625,1,6,1,1.92489624023438,66.4711685180664,,,,,,,,,,,,,,,,
,3931698603.7535,299.91584777832,6648.76123046875,0.00124021238150375,8.16179209935318E-7,1,1.99850670813958,40.0298881530762,1.99524837653469,15.1699995622039,0.0142860523354468,0.00239249616548008,0.25,-1.07577705843334E-5,0.00124018105648096,-9.95293280998747E-6,299.914916992188,299.914916992188,6628.70166015625,6668.82080078125,47.8809998310435,17.2662148031612,,0,0,0,80,299.916778564453,1,6,1,1.91238403320313,65.9824066162109,,,,,,,,,,,,,,,,
,3931698631.719,299.914993286133,7203.44555664062,0.00122800012926729,8.08082717836001E-7,1,1.99850670813958,40.0298881530762,1.99516175239898,15.1699995622039,0.0141377280962312,0.00240884647024431,0.25,-7.17311068949848E-6,0.00122796688389971,-6.3763369430114E-6,299.9140625,299.9140625,7183.3876953125,7223.50341796875,47.8700570317743,17.2697448435295,,0,0,0,80,299.915924072266,1,6,1,1.91741943359375,65.9824066162109,,,,,,,,,,,,,,,,
,3931698659.6815,299.915786743164,7761.31591796875,0.00121547762445995,5.96485648540287E-7,1,1.99850670813958,40.0298881530762,1.99520584757133,15.1699995622039,0.0139977685111822,0.00236216299499114,0.25,-9.02756971716983E-6,0.00121544594914236,-8.23889824564253E-6,299.915069580078,299.915069580078,7741.0576171875,7781.57421875,48.370299284082,17.2665298765764,,0,0,0,80,299.91650390625,1,6,1,1.92398071289062,66.4711685180664,,,,,,,,,,,,,,,,
,3931698687.6815,299.915573120117,8318.6103515625,0.00120170437851565,7.81463988217003E-7,1,1.99850670813958,40.0298881530762,1.99521912492564,15.1699995622039,0.0138380390791606,0.00234222589878624,0.25,-8.33271127177702E-6,0.00120167268703804,-7.55302877485896E-6,299.914642333984,299.914642333984,8299.818359375,8337.40234375,48.238204064332,17.266257217989,,0,0,0,80,299.91650390625,1,6,1,1.91604614257813,66.4711685180664,,,,,,,,,,,,,,,,
,3931698715.65,299.915786743164,8873.88671875,0.00118845872642932,8.25701266411758E-7,1,1.99850670813958,40.0298881530762,1.99528407260946,15.1699995622039,0.0136893232990055,0.0022973104638644,0.25,-9.90767042464064E-6,0.00118842846262156,-9.13656542466285E-6,299.915924072266,299.915924072266,8853.720703125,8894.052734375,47.9302424277551,17.2646917480324,,0,0,0,80,299.915649414063,1,6,1,1.91177368164062,66.4711685180664,,,,,,,,,,,,,,,,
,3931698743.6305,299.914703369141,9429.625,0.00117782932172439,9.06636572475187E-7,1,1.99850670813958,40.0298881530762,1.99511273496942,15.1699995622039,0.0135659185188583,0.00227568832032021,0.25,-9.89610003510547E-6,0.00117779941162803,-9.1319208053163E-6,299.914337158203,299.914337158203,9409.4560546875,9449.7939453125,48.0123134222743,17.2701986069559,,0,0,0,80,299.91650390625,1,6,1,1.929931640625,66.4711685180664,,,,,,,,,,,,,,,,
,3931698771.6375,299.915924072266,9988.43017578125,0.00116392636147238,8.59759514225408E-7,1,1.99850670813958,40.0298881530762,1.99531781064171,15.1699995622039,0.0134065981842055,0.00225200606764192,0.25,-9.52221909337048E-6,0.00116389660771126,-8.76710617756318E-6,299.915344238281,299.915344238281,9968.2783203125,10008.58203125,48.1428453849859,17.2640142743181,,0,0,0,80,299.91650390625,1,6,1,1.92398071289062,66.4711685180664,,,,,,,,,,,,,,,,
,3931698799.5795,299.913925170898,10543.8227539062,0.00114962292607969,9.56987940052473E-7,1,1.99850670813958,40.0298881530762,1.99530325050173,15.1699995622039,0.0132445511548582,0.00220844976609281,0.25,-1.07846089026817E-5,0.0011495944894656,-1.00387620040429E-5,299.9140625,299.9140625,10523.890625,10563.7548828125,48.1178332723705,17.2645259735286,,0,0,0,80,299.913787841797,1,6,1,1.9140625,65.9824066162109,,,,,,,,,,,,,,,,
,3931698827.603,299.915344238281,11099.6489257813,0.00113732201789716,7.35101735384819E-7,1,1.99850670813958,40.0298881530762,1.99524654572268,15.1699995622039,0.013099703530057,0.00220046921414426,0.25,-9.30327240303833E-6,0.00113729296521828,-8.56548644798505E-6,299.915344238281,299.915344238281,11080.9697265625,11118.328125,47.8129981498704,17.2643616932284,,0,0,0,80,299.915924072266,1,6,1,1.91452026367187,66.4711685180664,,,,,,,,,,,,,,,,
,3931698855.5535,299.915710449219,11656.3369140625,0.00112330973604311,9.1585200351489E-7,1,1.99850670813958,40.0298881530762,1.99531909985841,15.1699995622039,0.0129408027383725,0.00216187996868531,0.25,-1.01932331067542E-5,0.00112328168628654,-9.4645414107619E-6,299.914916992188,299.914916992188,11636.1806640625,11676.4931640625,48.1780186683513,17.2648254372978,,0,0,0,80,299.91650390625,1,6,1,1.92672729492187,66.4711685180664,,,,,,,,,,,,,,,,
,3931698883.545,299.91569519043,12213.1030273437,0.00110823430144871,8.22990836838875E-7,1,1.99850670813958,40.0298881530762,1.99517882415441,15.1699995622039,0.0127702946357832,0.0021098633162072,0.25,-1.20438786247424E-5,0.00110820792034032,-1.13249393300206E-5,299.914764404297,299.914764404297,12193.01953125,12233.1865234375,47.7715718383512,17.2674701456599,,0,0,0,80,299.916625976562,1,6,1,1.91162109375,66.4711685180664,,,,,,,,,,,,,,,,
,3931698911.514,299.915130615234,12769.3833007813,0.00109643498026532,9.19176165779737E-7,1,1.99850670813958,40.0298881530762,1.99492478805236,15.1599999517202,0.0126324637973432,0.00208890707620957,0.25,-1.17621957756098E-5,0.00109640879813087,-1.10509485227402E-5,299.914764404297,299.914764404297,12749.0703125,12789.6962890625,47.9669789681589,17.2779291803107,,0,0,0,80,299.915496826172,1,6,1,1.91604614257813,63.5386123657227,,,,,,,,,,,,,,,,
,3931698939.495,299.914855957031,13328.4462890625,0.00108021623883824,6.80898074844675E-7,1,1.99850670813958,40.0298881530762,1.99525719845728,15.1699995622039,0.0124427417011112,0.00208591426916326,0.25,-9.19062963585133E-6,0.00108018889962284,-8.49001073478386E-6,299.913635253906,299.913635253906,13308.072265625,13348.8203125,48.1459718990628,17.2647577305463,,0,0,0,80,299.915069580078,1,6,1,1.91207885742187,66.4711685180664,,,,,,,,,,,,,,,,
,3931698967.4595,299.915344238281,13885.0014648438,0.00106407836331582,7.73395150184933E-7,1,1.99850670813958,40.0298881530762,1.99524175599511,15.1699995622039,0.0122598849397793,0.00203703119300574,0.25,-1.05926859552447E-5,0.00106405242148112,-9.90252150702951E-6,299.914764404297,299.914764404297,13864.99609375,13905.0068359375,48.0693723041782,17.2671485845642,,0,0,0,80,299.915924072266,1,6,1,1.92489624023438,66.4711685180664,,,,,,,,,,,,,,,,
,3931698995.4275,299.91535949707,14440.6284179687,0.00105207870265363,7.87475081571143E-7,1,1.99850670813958,40.0298881530762,1.99524437840184,15.1699995622039,0.0121244725552129,0.00199803338455158,0.25,-1.18668244060733E-5,0.0010520539594839,-1.11844336762609E-5,299.914642333984,299.914642333984,14420.4765625,14460.7802734375,48.3288729725628,17.2653148634711,,0,0,0,80,299.916076660156,1,6,1,1.9256591796875,65.9824066162109,,,,,,,,,,,,,,,,
,3931699023.416,299.914642333984,14988.2788085938,0.0010363420001444,1.61765484433309E-6,1,1.99850670813958,40.0298881530762,1.99520459407051,15.1699995622039,0.0119427818290551,0.00196871176706853,0.25,-1.16369233338409E-5,0.0010363176134691,-1.09647724174595E-5,299.914215087891,299.914215087891,14976.994140625,14999.5634765625,48.0474867056397,17.2669676636092,,0,0,0,80,299.915649414063,1,4,1,1.92535400390625,66.4711685180664,,,,,,,,,,,,,,,,